
The following have been reloaded with a version change:
  1) gcc/14.2.0 => gcc/10.1.0


The following have been reloaded with a version change:
  1) gcc/10.1.0 => gcc/14.2.0

Lmod Warning:
-------------------------------------------------------------------------------
The following dependent module(s) are not currently loaded: gcc/10.1.0
(required by: proj/9.1.0)
-------------------------------------------------------------------------------



/home/users/epavia/.local/lib/python3.9/site-packages/pygeoprocessing/slurm_utils.py:58: UserWarning: GDAL's cache max exceeds the memory SLURM has allocated for this node. The process will probably be killed by the kernel's oom-killer. GDAL_CACHEMAX=10053548236 (interpreted as 9587.81074142456 MB), SLURM_MEM_PER_NODE=8192
  warnings.warn(message)
/home/users/epavia/.local/lib/python3.9/site-packages/urllib3/__init__.py:35: NotOpenSSLWarning: urllib3 v2 only supports OpenSSL 1.1.1+, currently the 'ssl' module is compiled with 'LibreSSL 3.2.1'. See: https://github.com/urllib3/urllib3/issues/3020
  warnings.warn(
/home/users/epavia/.local/lib/python3.9/site-packages/pydantic/_internal/_fields.py:132: UserWarning: Field "model_id" in ModelSpec has conflict with protected namespace "model_".

You may be able to resolve this warning by setting `model_config['protected_namespaces'] = ()`.
  warnings.warn(
/home/users/epavia/.local/lib/python3.9/site-packages/pydantic/_internal/_fields.py:132: UserWarning: Field "model_title" in ModelSpec has conflict with protected namespace "model_".

You may be able to resolve this warning by setting `model_config['protected_namespaces'] = ()`.
  warnings.warn(

09/22/2025 10:52:48  (natcap.invest.urban_cooling_model) urban_cooling_model.execute(551) INFO Starting Urban Cooling Model
09/22/2025 10:52:48  (taskgraph.Task) Task._create_taskgraph_table_schema(222) ERROR /oak/stanford/groups/gdaily/users/epavia/WellcomeTrustProjectData/2_postprocess_intermediate/UCM_official_runs/scenario1/work_and_energy_runs/taskgraph_cache/taskgraph_data.db exists, but is incompatible somehow. Deleting and making a new one.
Traceback (most recent call last):
  File "/home/users/epavia/.local/lib/python3.9/site-packages/taskgraph/Task.py", line 189, in _create_taskgraph_table_schema
    raise ValueError(f'missing table {expected_table_name}')
ValueError: missing table global_variables
Traceback (most recent call last):
  File "/home/users/epavia/urban-cooling-health/code/Urban_Cooling_Modeling_Runs/execute_invest_urban_cooling_model_scenario1.py", line 80, in <module>
    natcap.invest.urban_cooling_model.execute(args)
  File "/home/users/epavia/.local/lib/python3.9/site-packages/natcap/invest/urban_cooling_model.py", line 609, in execute
    lulc_raster_info = pygeoprocessing.get_raster_info(
  File "src/pygeoprocessing/geoprocessing_core.pyx", line 77, in pygeoprocessing.geoprocessing_core.gdal_use_exceptions.wrapper
  File "src/pygeoprocessing/geoprocessing_core.pyx", line 78, in pygeoprocessing.geoprocessing_core.gdal_use_exceptions.wrapper
  File "/home/users/epavia/.local/lib/python3.9/site-packages/pygeoprocessing/geoprocessing.py", line 2090, in get_raster_info
    raster = gdal.OpenEx(raster_path, gdal.OF_RASTER)
  File "/home/users/epavia/.local/lib/python3.9/site-packages/osgeo/gdal.py", line 4236, in OpenEx
    return _gdal.OpenEx(*args, **kwargs)
RuntimeError: /oak/stanford/groups/gdaily/users/epavia/WellcomeTrustProjectData/1_preprocess\UrbanCoolingModel\OfficialWorkingInputs\LULC\LCM2023_London_10m_clip2aoi_tcc24_scenario1_pavement.tif: No such file or directory
