
The following have been reloaded with a version change:
  1) gcc/14.2.0 => gcc/10.1.0


The following have been reloaded with a version change:
  1) gcc/10.1.0 => gcc/14.2.0

Lmod Warning:
-------------------------------------------------------------------------------
The following dependent module(s) are not currently loaded: gcc/10.1.0
(required by: proj/9.1.0)
-------------------------------------------------------------------------------



/home/users/epavia/.local/lib/python3.9/site-packages/pygeoprocessing/slurm_utils.py:58: UserWarning: GDAL's cache max exceeds the memory SLURM has allocated for this node. The process will probably be killed by the kernel's oom-killer. GDAL_CACHEMAX=10053548236 (interpreted as 9587.81074142456 MB), SLURM_MEM_PER_NODE=8192
  warnings.warn(message)
/home/users/epavia/.local/lib/python3.9/site-packages/pygeoprocessing/slurm_utils.py:58: UserWarning: GDAL's cache max exceeds the memory SLURM has allocated for this node. The process will probably be killed by the kernel's oom-killer. GDAL_CACHEMAX=10053548236 (interpreted as 9587.81074142456 MB), SLURM_MEM_PER_NODE=8192
  warnings.warn(message)
/home/users/epavia/.local/lib/python3.9/site-packages/pygeoprocessing/slurm_utils.py:58: UserWarning: GDAL's cache max exceeds the memory SLURM has allocated for this node. The process will probably be killed by the kernel's oom-killer. GDAL_CACHEMAX=10053548236 (interpreted as 9587.81074142456 MB), SLURM_MEM_PER_NODE=8192
  warnings.warn(message)
/home/users/epavia/.local/lib/python3.9/site-packages/urllib3/__init__.py:35: NotOpenSSLWarning: urllib3 v2 only supports OpenSSL 1.1.1+, currently the 'ssl' module is compiled with 'LibreSSL 3.2.1'. See: https://github.com/urllib3/urllib3/issues/3020
  warnings.warn(
/home/users/epavia/.local/lib/python3.9/site-packages/urllib3/__init__.py:35: NotOpenSSLWarning: urllib3 v2 only supports OpenSSL 1.1.1+, currently the 'ssl' module is compiled with 'LibreSSL 3.2.1'. See: https://github.com/urllib3/urllib3/issues/3020
  warnings.warn(
/home/users/epavia/.local/lib/python3.9/site-packages/urllib3/__init__.py:35: NotOpenSSLWarning: urllib3 v2 only supports OpenSSL 1.1.1+, currently the 'ssl' module is compiled with 'LibreSSL 3.2.1'. See: https://github.com/urllib3/urllib3/issues/3020
  warnings.warn(
/home/users/epavia/.local/lib/python3.9/site-packages/pydantic/_internal/_fields.py:132: UserWarning: Field "model_id" in ModelSpec has conflict with protected namespace "model_".

You may be able to resolve this warning by setting `model_config['protected_namespaces'] = ()`.
  warnings.warn(
/home/users/epavia/.local/lib/python3.9/site-packages/pydantic/_internal/_fields.py:132: UserWarning: Field "model_title" in ModelSpec has conflict with protected namespace "model_".

You may be able to resolve this warning by setting `model_config['protected_namespaces'] = ()`.
  warnings.warn(

09/22/2025 10:45:44  (natcap.invest.urban_cooling_model) urban_cooling_model.execute(551) INFO Starting Urban Cooling Model
/home/users/epavia/.local/lib/python3.9/site-packages/pydantic/_internal/_fields.py:132: UserWarning: Field "model_id" in ModelSpec has conflict with protected namespace "model_".

You may be able to resolve this warning by setting `model_config['protected_namespaces'] = ()`.
  warnings.warn(
/home/users/epavia/.local/lib/python3.9/site-packages/pydantic/_internal/_fields.py:132: UserWarning: Field "model_title" in ModelSpec has conflict with protected namespace "model_".

You may be able to resolve this warning by setting `model_config['protected_namespaces'] = ()`.
  warnings.warn(
G:\Shared drives\Wellcome Trust Project Data\2_postprocess_intermediate\UCM_official_runs\scenario4\current_climate
09/22/2025 10:45:44  (natcap.invest.urban_cooling_model) urban_cooling_model.execute(551) INFO Starting Urban Cooling Model
/home/users/epavia/.local/lib/python3.9/site-packages/pydantic/_internal/_fields.py:132: UserWarning: Field "model_id" in ModelSpec has conflict with protected namespace "model_".

You may be able to resolve this warning by setting `model_config['protected_namespaces'] = ()`.
  warnings.warn(
/home/users/epavia/.local/lib/python3.9/site-packages/pydantic/_internal/_fields.py:132: UserWarning: Field "model_title" in ModelSpec has conflict with protected namespace "model_".

You may be able to resolve this warning by setting `model_config['protected_namespaces'] = ()`.
  warnings.warn(
Traceback (most recent call last):
  File "/home/users/epavia/urban-cooling-health/code/Urban_Cooling_Modeling_Runs/execute_invest_urban_cooling_model_scenario4_10prc_TCC.py", line 69, in <module>
    natcap.invest.urban_cooling_model.execute(args)
  File "/home/users/epavia/.local/lib/python3.9/site-packages/natcap/invest/urban_cooling_model.py", line 556, in execute
    biophysical_df = MODEL_SPEC.get_input(
  File "/home/users/epavia/.local/lib/python3.9/site-packages/natcap/invest/spec.py", line 795, in get_validated_dataframe
G:\Shared drives\Wellcome Trust Project Data\2_postprocess_intermediate\UCM_official_runs\scenario4\current_climate
09/22/2025 10:45:44  (natcap.invest.urban_cooling_model) urban_cooling_model.execute(551) INFO Starting Urban Cooling Model
    df = utils.read_csv_to_dataframe(csv_path, **read_csv_kwargs)
  File "/home/users/epavia/.local/lib/python3.9/site-packages/natcap/invest/utils.py", line 457, in read_csv_to_dataframe
Traceback (most recent call last):
  File "/home/users/epavia/urban-cooling-health/code/Urban_Cooling_Modeling_Runs/execute_invest_urban_cooling_model_scenario4_10prc_TCC.py", line 69, in <module>
    df = pandas.read_csv(
  File "/home/users/epavia/.local/lib/python3.9/site-packages/pandas/io/parsers/readers.py", line 1026, in read_csv
    natcap.invest.urban_cooling_model.execute(args)
  File "/home/users/epavia/.local/lib/python3.9/site-packages/natcap/invest/urban_cooling_model.py", line 556, in execute
    return _read(filepath_or_buffer, kwds)
  File "/home/users/epavia/.local/lib/python3.9/site-packages/pandas/io/parsers/readers.py", line 620, in _read
    biophysical_df = MODEL_SPEC.get_input(
  File "/home/users/epavia/.local/lib/python3.9/site-packages/natcap/invest/spec.py", line 795, in get_validated_dataframe
    parser = TextFileReader(filepath_or_buffer, **kwds)
  File "/home/users/epavia/.local/lib/python3.9/site-packages/pandas/io/parsers/readers.py", line 1620, in __init__
    df = utils.read_csv_to_dataframe(csv_path, **read_csv_kwargs)
  File "/home/users/epavia/.local/lib/python3.9/site-packages/natcap/invest/utils.py", line 457, in read_csv_to_dataframe
    self._engine = self._make_engine(f, self.engine)
  File "/home/users/epavia/.local/lib/python3.9/site-packages/pandas/io/parsers/readers.py", line 1880, in _make_engine
    df = pandas.read_csv(
  File "/home/users/epavia/.local/lib/python3.9/site-packages/pandas/io/parsers/readers.py", line 1026, in read_csv
    self.handles = get_handle(
  File "/home/users/epavia/.local/lib/python3.9/site-packages/pandas/io/common.py", line 873, in get_handle
    return _read(filepath_or_buffer, kwds)
  File "/home/users/epavia/.local/lib/python3.9/site-packages/pandas/io/parsers/readers.py", line 620, in _read
    handle = open(
FileNotFoundError: [Errno 2] No such file or directory: 'G:\\Shared drives\\Wellcome Trust Project Data\\1_preprocess\\UrbanCoolingModel\\OfficialWorkingInputs\\LULC\\Biophysical_table_ukech_2021_london_with_TCC.csv'
    parser = TextFileReader(filepath_or_buffer, **kwds)
  File "/home/users/epavia/.local/lib/python3.9/site-packages/pandas/io/parsers/readers.py", line 1620, in __init__
    self._engine = self._make_engine(f, self.engine)
  File "/home/users/epavia/.local/lib/python3.9/site-packages/pandas/io/parsers/readers.py", line 1880, in _make_engine
    self.handles = get_handle(
  File "/home/users/epavia/.local/lib/python3.9/site-packages/pandas/io/common.py", line 873, in get_handle
    handle = open(
FileNotFoundError: [Errno 2] No such file or directory: 'G:\\Shared drives\\Wellcome Trust Project Data\\1_preprocess\\UrbanCoolingModel\\OfficialWorkingInputs\\LULC\\Biophysical_table_ukech_2021_london_with_TCC.csv'
