
The following have been reloaded with a version change:
  1) gcc/14.2.0 => gcc/10.1.0


The following have been reloaded with a version change:
  1) gcc/10.1.0 => gcc/14.2.0

Lmod Warning:
-------------------------------------------------------------------------------
The following dependent module(s) are not currently loaded: gcc/10.1.0
(required by: proj/9.1.0)
-------------------------------------------------------------------------------



/home/users/epavia/.local/lib/python3.9/site-packages/pygeoprocessing/slurm_utils.py:58: UserWarning: GDAL's cache max exceeds the memory SLURM has allocated for this node. The process will probably be killed by the kernel's oom-killer. GDAL_CACHEMAX=10053548236 (interpreted as 9587.81074142456 MB), SLURM_MEM_PER_NODE=8192
  warnings.warn(message)
/home/users/epavia/.local/lib/python3.9/site-packages/pygeoprocessing/slurm_utils.py:58: UserWarning: GDAL's cache max exceeds the memory SLURM has allocated for this node. The process will probably be killed by the kernel's oom-killer. GDAL_CACHEMAX=10053548236 (interpreted as 9587.81074142456 MB), SLURM_MEM_PER_NODE=8192
  warnings.warn(message)
/home/users/epavia/.local/lib/python3.9/site-packages/pygeoprocessing/slurm_utils.py:58: UserWarning: GDAL's cache max exceeds the memory SLURM has allocated for this node. The process will probably be killed by the kernel's oom-killer. GDAL_CACHEMAX=10053548236 (interpreted as 9587.81074142456 MB), SLURM_MEM_PER_NODE=8192
  warnings.warn(message)
/home/users/epavia/.local/lib/python3.9/site-packages/urllib3/__init__.py:35: NotOpenSSLWarning: urllib3 v2 only supports OpenSSL 1.1.1+, currently the 'ssl' module is compiled with 'LibreSSL 3.2.1'. See: https://github.com/urllib3/urllib3/issues/3020
  warnings.warn(
/home/users/epavia/.local/lib/python3.9/site-packages/urllib3/__init__.py:35: NotOpenSSLWarning: urllib3 v2 only supports OpenSSL 1.1.1+, currently the 'ssl' module is compiled with 'LibreSSL 3.2.1'. See: https://github.com/urllib3/urllib3/issues/3020
  warnings.warn(
/home/users/epavia/.local/lib/python3.9/site-packages/urllib3/__init__.py:35: NotOpenSSLWarning: urllib3 v2 only supports OpenSSL 1.1.1+, currently the 'ssl' module is compiled with 'LibreSSL 3.2.1'. See: https://github.com/urllib3/urllib3/issues/3020
  warnings.warn(
/home/users/epavia/.local/lib/python3.9/site-packages/pydantic/_internal/_fields.py:132: UserWarning: Field "model_id" in ModelSpec has conflict with protected namespace "model_".

You may be able to resolve this warning by setting `model_config['protected_namespaces'] = ()`.
  warnings.warn(
/home/users/epavia/.local/lib/python3.9/site-packages/pydantic/_internal/_fields.py:132: UserWarning: Field "model_title" in ModelSpec has conflict with protected namespace "model_".

You may be able to resolve this warning by setting `model_config['protected_namespaces'] = ()`.
  warnings.warn(

09/22/2025 10:49:06  (natcap.invest.urban_cooling_model) urban_cooling_model.execute(551) INFO Starting Urban Cooling Model
/home/users/epavia/.local/lib/python3.9/site-packages/pydantic/_internal/_fields.py:132: UserWarning: Field "model_id" in ModelSpec has conflict with protected namespace "model_".

You may be able to resolve this warning by setting `model_config['protected_namespaces'] = ()`.
  warnings.warn(
/home/users/epavia/.local/lib/python3.9/site-packages/pydantic/_internal/_fields.py:132: UserWarning: Field "model_title" in ModelSpec has conflict with protected namespace "model_".

You may be able to resolve this warning by setting `model_config['protected_namespaces'] = ()`.
  warnings.warn(
Traceback (most recent call last):
  File "/home/users/epavia/urban-cooling-health/code/Urban_Cooling_Modeling_Runs/execute_invest_urban_cooling_model_scenario4_30prc_TCC.py", line 48, in <module>
    args['aoi_vector_path'] = os.path.join(path_prefix, '1_preprocess/UrbanCoolingModel/OfficialWorkingInputs/AOIs/London_Borough_aoi.shp')
NameError: name 'os' is not defined
